An error occurred while trying to fetch botp/stable-diffusion-v1-5-inpainting: botp/stable-diffusion-v1-5-inpainting does not appear to have a file named diffusion_pytorch_model.safetensors.
Defaulting to unsafe serialization. Pass `allow_pickle=False` to raise an error instead.
You are using a model of type clip_text_model to instantiate a model of type . This is not supported for all configurations of models and can yield errors.
Processing batches: 100%|█████████████████████████████████████████████████████████████████████| 1/1 [00:00<00:00,  1.12it/s]
An error occurred while trying to fetch /home/tiennv/trang/chaos/controlnext/weight_pretrain/unet_inpainting: Error no file named diffusion_pytorch_model.safetensors found in directory /home/tiennv/trang/chaos/controlnext/weight_pretrain/unet_inpainting.
Defaulting to unsafe serialization. Pass `allow_pickle=False` to raise an error instead.
/home/tiennv/.conda/envs/chaos/lib/python3.10/site-packages/lightning/pytorch/utilities/parsing.py:208: Attribute 'unet' is an instance of `nn.Module` and is already saved during checkpointing. It is recommended to ignore them using `self.save_hyperparameters(ignore=['unet'])`.
GPU available: True (cuda), used: True
TPU available: False, using: 0 TPU cores
HPU available: False, using: 0 HPUs
You are using a CUDA device ('NVIDIA GeForce RTX 3090') that has Tensor Cores. To properly utilize them, you should set `torch.set_float32_matmul_precision('medium' | 'high')` which will trade-off precision for performance. For more details, read https://pytorch.org/docs/stable/generated/torch.set_float32_matmul_precision.html#torch.set_float32_matmul_precision
/home/tiennv/.conda/envs/chaos/lib/python3.10/site-packages/lightning/pytorch/loggers/wandb.py:396: There is a wandb run already in progress and newly created instances of `WandbLogger` will reuse this run. If this is not desired, call `wandb.finish()` before instantiating `WandbLogger`.
/home/tiennv/.conda/envs/chaos/lib/python3.10/site-packages/lightning/pytorch/callbacks/model_checkpoint.py:654: Checkpoint directory /mnt/Userdrive/tiennv/trang/chaos/trash/output/checkpoints exists and is not empty.
Restoring states from the checkpoint path at /home/tiennv/trang/chaos/trash/output/checkpoints/model-epoch=994-train_loss=0.0000.ckpt
LOCAL_RANK: 0 - CUDA_VISIBLE_DEVICES: [0]
/home/tiennv/.conda/envs/chaos/lib/python3.10/site-packages/lightning/pytorch/core/optimizer.py:377: Found unsupported keys in the optimizer configuration: {'scheduler', 'interval'}

  | Name | Type                 | Params | Mode
-----------------------------------------------------
0 | unet | UNet2DConditionModel | 859 M  | eval
-----------------------------------------------------
859 M     Trainable params
0         Non-trainable params
859 M     Total params
3,438.141 Total estimated model params size (MB)
32        Modules in train mode
686       Modules in eval mode
Restored all states from the checkpoint at /home/tiennv/trang/chaos/trash/output/checkpoints/model-epoch=994-train_loss=0.0000.ckpt
Epoch 1999: 100%|██████████████| 1/1 [00:01<00:00,  0.80it/s, v_num=8f5z, train_loss_step=2.13e-5, train_loss_epoch=2.13e-5]
/home/tiennv/.conda/envs/chaos/lib/python3.10/site-packages/torch/nn/modules/conv.py:456: UserWarning: Plan failed with a cudnnException: CUDNN_BACKEND_EXECUTION_PLAN_DESCRIPTOR: cudnnFinalize Descriptor Failed cudnn_status: CUDNN_STATUS_NOT_SUPPORTED (Triggered internally at /opt/conda/conda-bld/pytorch_1712608935911/work/aten/src/ATen/native/cudnn/Conv_v8.cpp:919.)
  return F.conv2d(input, weight, bias, self.stride,
`Trainer.fit` stopped: `max_epochs=2000` reached.
Training complete
