An error occurred while trying to fetch /home/weight_pretrain/unet: Error no file named diffusion_pytorch_model.safetensors found in directory /home/weight_pretrain/unet.
Defaulting to unsafe serialization. Pass `allow_pickle=False` to raise an error instead.
/opt/conda/envs/chaos/lib/python3.10/site-packages/lightning/pytorch/utilities/parsing.py:208: Attribute 'unet' is an instance of `nn.Module` and is already saved during checkpointing. It is recommended to ignore them using `self.save_hyperparameters(ignore=['unet'])`.
GPU available: True (cuda), used: True
TPU available: False, using: 0 TPU cores
HPU available: False, using: 0 HPUs
You are using a CUDA device ('NVIDIA GeForce RTX 3090') that has Tensor Cores. To properly utilize them, you should set `torch.set_float32_matmul_precision('medium' | 'high')` which will trade-off precision for performance. For more details, read https://pytorch.org/docs/stable/generated/torch.set_float32_matmul_precision.html#torch.set_float32_matmul_precision
/opt/conda/envs/chaos/lib/python3.10/site-packages/lightning/pytorch/loggers/wandb.py:396: There is a wandb run already in progress and newly created instances of `WandbLogger` will reuse this run. If this is not desired, call `wandb.finish()` before instantiating `WandbLogger`.
Restoring states from the checkpoint path at /home/save_checkpoint/checkpoints/model-epoch=97-train_loss=0.0018.ckpt
Traceback (most recent call last):
  File "/home/CATDF-Diffusion/script_run/../train.py", line 292, in <module>
    main()
  File "/home/CATDF-Diffusion/script_run/../train.py", line 280, in main
    trainer.fit(
  File "/opt/conda/envs/chaos/lib/python3.10/site-packages/lightning/pytorch/trainer/trainer.py", line 538, in fit
    call._call_and_handle_interrupt(
  File "/opt/conda/envs/chaos/lib/python3.10/site-packages/lightning/pytorch/trainer/call.py", line 47, in _call_and_handle_interrupt
    return trainer_fn(*args, **kwargs)
  File "/opt/conda/envs/chaos/lib/python3.10/site-packages/lightning/pytorch/trainer/trainer.py", line 574, in _fit_impl
    self._run(model, ckpt_path=ckpt_path)
  File "/opt/conda/envs/chaos/lib/python3.10/site-packages/lightning/pytorch/trainer/trainer.py", line 950, in _run
    self._checkpoint_connector._restore_modules_and_callbacks(ckpt_path)
  File "/opt/conda/envs/chaos/lib/python3.10/site-packages/lightning/pytorch/trainer/connectors/checkpoint_connector.py", line 397, in _restore_modules_and_callbacks
    self.resume_start(checkpoint_path)
  File "/opt/conda/envs/chaos/lib/python3.10/site-packages/lightning/pytorch/trainer/connectors/checkpoint_connector.py", line 79, in resume_start
    loaded_checkpoint = self.trainer.strategy.load_checkpoint(checkpoint_path)
  File "/opt/conda/envs/chaos/lib/python3.10/site-packages/lightning/pytorch/strategies/strategy.py", line 367, in load_checkpoint
    return self.checkpoint_io.load_checkpoint(checkpoint_path)
  File "/opt/conda/envs/chaos/lib/python3.10/site-packages/lightning/fabric/plugins/io/torch_io.py", line 81, in load_checkpoint
    raise FileNotFoundError(f"Checkpoint file not found: {path}")
FileNotFoundError: Checkpoint file not found: /home/save_checkpoint/checkpoints/model-epoch=97-train_loss=0.0018.ckpt
