An error occurred while trying to fetch /home/weight_pretrain/unet: Error no file named diffusion_pytorch_model.safetensors found in directory /home/weight_pretrain/unet.
Defaulting to unsafe serialization. Pass `allow_pickle=False` to raise an error instead.
/opt/conda/envs/chaos/lib/python3.10/site-packages/lightning/pytorch/utilities/parsing.py:208: Attribute 'unet' is an instance of `nn.Module` and is already saved during checkpointing. It is recommended to ignore them using `self.save_hyperparameters(ignore=['unet'])`.
GPU available: True (cuda), used: True
TPU available: False, using: 0 TPU cores
HPU available: False, using: 0 HPUs
You are using a CUDA device ('NVIDIA GeForce RTX 3090') that has Tensor Cores. To properly utilize them, you should set `torch.set_float32_matmul_precision('medium' | 'high')` which will trade-off precision for performance. For more details, read https://pytorch.org/docs/stable/generated/torch.set_float32_matmul_precision.html#torch.set_float32_matmul_precision
/opt/conda/envs/chaos/lib/python3.10/site-packages/lightning/pytorch/loggers/wandb.py:396: There is a wandb run already in progress and newly created instances of `WandbLogger` will reuse this run. If this is not desired, call `wandb.finish()` before instantiating `WandbLogger`.
LOCAL_RANK: 0 - CUDA_VISIBLE_DEVICES: [0]
Traceback (most recent call last):
  File "/home/CATDF-Diffusion/script_run/../train.py", line 285, in <module>
    main()
  File "/home/CATDF-Diffusion/script_run/../train.py", line 274, in main
    trainer.fit(
  File "/opt/conda/envs/chaos/lib/python3.10/site-packages/lightning/pytorch/trainer/trainer.py", line 538, in fit
    call._call_and_handle_interrupt(
  File "/opt/conda/envs/chaos/lib/python3.10/site-packages/lightning/pytorch/trainer/call.py", line 47, in _call_and_handle_interrupt
    return trainer_fn(*args, **kwargs)
  File "/opt/conda/envs/chaos/lib/python3.10/site-packages/lightning/pytorch/trainer/trainer.py", line 574, in _fit_impl
    self._run(model, ckpt_path=ckpt_path)
  File "/opt/conda/envs/chaos/lib/python3.10/site-packages/lightning/pytorch/trainer/trainer.py", line 957, in _run
    self.strategy.setup(self)
  File "/opt/conda/envs/chaos/lib/python3.10/site-packages/lightning/pytorch/strategies/strategy.py", line 158, in setup
    self.setup_optimizers(trainer)
  File "/opt/conda/envs/chaos/lib/python3.10/site-packages/lightning/pytorch/strategies/strategy.py", line 138, in setup_optimizers
    self.optimizers, self.lr_scheduler_configs = _init_optimizers_and_lr_schedulers(self.lightning_module)
  File "/opt/conda/envs/chaos/lib/python3.10/site-packages/lightning/pytorch/core/optimizer.py", line 179, in _init_optimizers_and_lr_schedulers
    optim_conf = call._call_lightning_module_hook(model.trainer, "configure_optimizers", pl_module=model)
  File "/opt/conda/envs/chaos/lib/python3.10/site-packages/lightning/pytorch/trainer/call.py", line 167, in _call_lightning_module_hook
    output = fn(*args, **kwargs)
  File "/home/CATDF-Diffusion/trainer.py", line 177, in configure_optimizers
    self.scheduler_optimizer_config.get_optimizer_parameters(),
  File "/home/CATDF-Diffusion/trainer.py", line 27, in get_optimizer_parameters
    optimizer_params = self.scheduler_optimizer_config.get_optimizer_parameters()
AttributeError: 'TrainableParameters' object has no attribute 'scheduler_optimizer_config'
